Workbook

Sheet Full Player List
A1: college_gsis_id | B1: position | C1: player_name | D1: season | E1: team | F1: school_code | G1: passing_attempts | H1: passing_completions | I1: passing_yards | J1: passing_completion_percentage | K1: passing_touchdowns | L1: passing_interceptions | M1: rushing_attempts | N1: rushing_yards | O1: rushing_touchdowns | P1: receiving_receptions | Q1: receiving_touchdowns | R1: receiving_yards | S1: defense_pass_breakups | T1: defense_qb_hurries | U1: defense_sacks | V1: defense_solo_tackles | W1: defense_total_tackles | X1: defense_tackles_for_loss | Y1: defense_interceptions | Z1: defense_touchdowns | AA1: kickreturns_avg | AB1: kickreturns_long | AC1: kickreturns_no | AD1: kickreturns_touchdowns | AE1: kickreturns_yards | AF1: puntreturns_avg | AG1: puntreturns_long | AH1: puntreturns_no | AI1: puntreturns_td | AJ1: puntreturns_yds | AK1: total_fumbles | AL1: total_fumbles_lost
A2: 158332 | B2: DT | C2: Garrett Marino | D2: 2017 | E2: UAB | F2: ALBI | S2: 2 | T2: 3 | U2: 1 | V2: 18 | W2: 29 | X2: 7.5 | Z2: 0 | AK2: 0 | AL2: 0
A3: 158332 | B3: DT | C3: Garrett Marino | D3: 2018 | E3: UAB | F3: ALBI | M3: 3 | N3: 5 | O3: 0 | P3: 1 | Q3: 0 | R3: -9 | S3: 0 | T3: 5 | U3: 3.5 | V3: 10 | W3: 19 | X3: 6.5 | Z3: 1 | AK3: 0 | AL3: 0
A4: 158332 | B4: DT | C4: Garrett Marino | D4: 2019 | E4: UAB | F4: ALBI | S4: 7 | T4: 4 | U4: 5.5 | V4: 29 | W4: 42 | X4: 13 | Z4: 0 | AK4: 0 | AL4: 0
A5: 172387 | B5: DS | C5: Austin Lee | D5: 2017 | E5: BYU | F5: UTBY | S5: 0 | T5: 0 | U5: 0 | V5: 10 | W5: 15 | X5: 0 | Z5: 0 | AK5: 0 | AL5: 0
A6: 172387 | B6: DS | C6: Austin Lee | D6: 2018 | E6: BYU | F6: UTBY | G6: 1 | H6: 0 | I6: 0 | J6: 0 | K6: 0 | L6: 0 | S6: 1 | T6: 0 | U6: 0 | V6: 21 | W6: 34 | X6: 1 | Y6: 2 | Z6: 0
A7: 172387 | B7: DS | C7: Austin Lee | D7: 2019 | E7: BYU | F7: UTBY | S7: 4 | T7: 0 | U7: 0 | V7: 36 | W7: 55 | X7: 2 | Y7: 1 | Z7: 1
A8: 172698 | B8: WR | C8: Nick Westbrook | D8: 2018 | E8: Indiana | F8: INUN | P8: 42 | Q8: 4 | R8: 590
A9: 172698 | B9: WR | C9: Nick Westbrook | D9: 2019 | E9: Indiana | F9: INUN | P9: 42 | Q9: 5 | R9: 572
A10: 172890 | B10: DC | C10: Chris Williamson | D10: 2018 | E10: Minnesota | F10: MNUN | S10: 4 | T10: 0 | U10: 1 | V10: 20 | W10: 32 | X10: 3.5 | Z10: 0
A11: 172890 | B11: DC | C11: Chris Williamson | D11: 2019 | E11: Minnesota | F11: MNUN | S11: 3 | T11: 1 | U11: 2.5 | V11: 36 | W11: 56 | X11: 4 | Y11: 1 | Z11: 1
A12: 173519 | B12: QB | C12: Kelly Bryant | D12: 2017 | E12: Clemson | F12: SCCL | G12: 398 | H12: 262 | I12: 2802 | J12: 0.658 | K12: 13 | L12: 8 | M12: 192 | N12: 665 | O12: 11 | S12: 0 | T12: 0 | U12: 0 | V12: 4 | W12: 4 | X12: 0 | Z12: 0 | AK12: 4 | AL12: 2
A13: 173519 | B13: QB | C13: Kelly Bryant | D13: 2018 | E13: Clemson | F13: SCCL | G13: 54 | H13: 36 | I13: 461 | J13: 0.667 | K13: 2 | L13: 1 | M13: 30 | N13: 130 | O13: 2 | AK13: 2 | AL13: 0
A14: 173519 | B14: QB | C14: Kelly Bryant | D14: 2019 | E14: Missouri | F14: MOUN | G14: 292 | H14: 181 | I14: 2215 | J14: 0.62 | K14: 15 | L14: 6 | M14: 106 | N14: 242 | O14: 1 | S14: 0 | T14: 0 | U14: 0 | V14: 2 | W14: 2 | X14: 0 | Z14: 0 | AK14: 4 | AL14: 2
A15: 173587 | B15: DS | C15: Jeremiah Dinson | D15: 2017 | E15: Auburn | F15: ALAU | S15: 3 | T15: 0 | U15: 1 | V15: 27 | W15: 41 | X15: 2.5 | Z15: 0 | AK15: 0 | AL15: 0
A16: 173587 | B16: DS | C16: Jeremiah Dinson | D16: 2018 | E16: Auburn | F16: ALAU | S16: 3 | T16: 1 | U16: 1 | V16: 25 | W16: 49 | X16: 3.5 | Y16: 2 | Z16: 0
A17: 173587 | B17: DS | C17: Jeremiah Dinson | D17: 2019 | E17: Auburn | F17: ALAU | S17: 1 | T17: 0 | U17: 2 | V17: 57 | W17: 88 | X17: 4.5 | Y17: 2 | Z17: 0 | AK17: 0 | AL17: 0
A18: 173646 | B18: DC | C18: Jace Whittaker | D18: 2017 | E18: Arizona | F18: AZUN | S18: 13 | T18: 0 | U18: 0 | V18: 39 | W18: 46 | X18: 2 | Y18: 3 | Z18: 1
A19: 173646 | B19: DC | C19: Jace Whittaker | D19: 2019 | E19: Arizona | F19: AZUN | S19: 6 | T19: 0 | U19: 1 | V19: 47 | W19: 55 | X19: 2 | Y19: 3 | Z19: 0
A20: 174215 | B20: DC | C20: John Reid | D20: 2018 | E20: Penn State | F20: PAST | S20: 8 | T20: 2 | U20: 0 | V20: 17 | W20: 24 | X20: 1 | Y20: 2 | Z20: 0
A21: 174215 | B21: DC | C21: John Reid | D21: 2019 | E21: Penn State | F21: PAST | S21: 8 | T21: 1 | U21: 1 | V21: 26 | W21: 37 | X21: 2.5 | Y21: 2 | Z21: 1
A22: 174315 | B22: DE | C22: James Smith-Williams | D22: 2017 | E22: NC State | F22: NCST | S22: 0 | T22: 0 | U22: 0.5 | V22: 5 | W22: 10 | X22: 1.5 | Z22: 0 | AF22: 11 | AG22: 11 | AH22: 1 | AI22: 0 | AJ22: 11 | AK22: 0 | AL22: 0
A23: 174315 | B23: DE | C23: James Smith-Williams | D23: 2018 | E23: NC State | F23: NCST | S23: 2 | T23: 4 | U23: 6 | V23: 16 | W23: 36 | X23: 9 | Z23: 0 | AK23: 0 | AL23: 0
A24: 174315 | B24: DE | C24: James Smith-Williams | D24: 2019 | E24: NC State | F24: NCST | S24: 0 | T24: 7 | U24: 1 | V24: 9 | W24: 20 | X24: 1 | Z24: 0
A25: 174449 | B25: DS | C25: Rodney Clemons | D25: 2017 | E25: SMU | F25: TXMU | S25: 10 | T25: 0 | U25: 1 | V25: 55 | W25: 67 | X25: 4 | Y25: 1 | Z25: 0 | AK25: 0 | AL25: 0
A26: 174449 | B26: DS | C26: Rodney Clemons | D26: 2018 | E26: SMU | F26: TXMU | S26: 4 | T26: 0 | U26: 0 | V26: 54 | W26: 72 | X26: 2.5 | Y26: 1 | Z26: 0
A27: 174449 | B27: DS | C27: Rodney Clemons | D27: 2019 | E27: SMU | F27: TXMU | S27: 9 | T27: 0 | U27: 0 | V27: 48 | W27: 77 | X27: 3 | Y27: 4 | Z27: 0 | AK27: 0 | AL27: 0
A28: 174850 | B28: RB | C28: LeVante Bellamy | D28: 2017 | E28: Western Michigan | F28: MIWE | M28: 49 | N28: 394 | O28: 3 | P28: 7 | Q28: 0 | R28: 54 | AA28: 18 | AB28: 18 | AC28: 1 | AD28: 0 | AE28: 18
A29: 174850 | B29: RB | C29: LeVante Bellamy | D29: 2018 | E29: Western Michigan | F29: MIWE | M29: 205 | N29: 1228 | O29: 6 | P29: 30 | Q29: 1 | R29: 185 | S29: 0 | T29: 0 | U29: 0 | V29: 1 | W29: 1 | X29: 0 | Z29: 0 | AA29: 18.2 | AB29: 27 | AC29: 14 | AD29: 0 | AE29: 255 | AK29: 4 | AL29: 3
A30: 174850 | B30: RB | C30: LeVante Bellamy | D30: 2019 | E30: Western Michigan | F30: MIWE | M30: 266 | N30: 1472 | O30: 23 | P30: 15 | Q30: 0 | R30: 55 | AK30: 1 | AL30: 1
A31: 181911 | B31: OB | C31: Casey Toohill | D31: 2017 | E31: Stanford | F31: CAST | S31: 0 | T31: 2 | U31: 1 | V31: 10 | W31: 18 | X31: 3 | Y31: 1 | Z31: 0 | AK31: 0 | AL31: 0
A32: 181911 | B32: OB | C32: Casey Toohill | D32: 2018 | E32: Stanford | F32: CAST | S32: 3 | T32: 6 | U32: 3 | V32: 14 | W32: 28 | X32: 5 | Z32: 0
A33: 181911 | B33: OB | C33: Casey Toohill | D33: 2019 | E33: Stanford | F33: CAST | S33: 1 | T33: 10 | U33: 8 | V33: 37 | W33: 57 | X33: 11.5 | Z33: 0
A34: 182164 | B34: IB | C34: Dante Olson | D34: 2017 | E34: Montana | F34: MTUN | S34: 0 | T34: 0 | U34: 0 | V34: 3 | W34: 3 | X34: 0 | Z34: 0
A35: 182164 | B35: IB | C35: Dante Olson | D35: 2019 | E35: Montana | F35: MTUN | S35: 0 | T35: 0 | U35: 0 | V35: 10 | W35: 14 | X35: 0 | Z35: 0
A36: 190013 | B36: DE | C36: Joe Gaziano | D36: 2017 | E36: Northwestern | F36: ILNW | S36: 5 | T36: 12 | U36: 9 | V36: 23 | W36: 35 | X36: 13 | Z36: 0
A37: 190013 | B37: DE | C37: Joe Gaziano | D37: 2018 | E37: Northwestern | F37: ILNW | S37: 3 | T37: 8 | U37: 7.5 | V37: 27 | W37: 44 | X37: 12.5 | Z37: 0 | AK37: 0 | AL37: 0
A38: 190013 | B38: DE | C38: Joe Gaziano | D38: 2019 | E38: Northwestern | F38: ILNW | S38: 5 | T38: 3 | U38: 9 | V38: 34 | W38: 49 | X38: 17 | Z38: 0 | AK38: 0 | AL38: 0
A39: 191527 | B39: WR | C39: Ja'Marcus Bradley | D39: 2017 | E39: Louisiana | F39: LASW | G39: 3 | H39: 0 | I39: 0 | J39: 0 | K39: 0 | L39: 0 | M39: 2 | N39: 25 | O39: 0 | P39: 39 | Q39: 2 | R39: 475 | S39: 1 | T39: 0 | U39: 0 | V39: 0 | W39: 0 | X39: 0 | Z39: 0
A40: 191527 | B40: WR | C40: Ja'Marcus Bradley | D40: 2018 | E40: Louisiana | F40: LASW | G40: 1 | H40: 1 | I40: 21 | J40: 1 | K40: 0 | L40: 0 | M40: 1 | N40: 5 | O40: 0 | P40: 40 | Q40: 10 | R40: 608 | AA40: 20.2 | AB40: 53 | AC40: 13 | AD40: 0 | AE40: 263 | AF40: 6.8 | AG40: 24 | AH40: 5 | AI40: 0 | AJ40: 34 | AK40: 1 | AL40: 0
...

Sheet RB
A1: college_gsis_id | B1: position | C1: player_name | D1: season | E1: team | F1: school_code | G1: rushing_attempts | H1: rushing_yards | I1: rushing_touchdowns | J1: receiving_receptions | K1: receiving_touchdowns | L1: receiving_yards
A2: 280152 | B2: RB | C2: Ronnie Rivers | G2: =671/5 -> 134.2 | H2: =3417/5 -> 683.4 | I2: =40/5 -> 8 | J2: 30 | K2: =11/5 -> 2.2 | L2: =1417/5 -> 283.4
A3: 310208 | B3: RB | C3: Pierre Strong | G3: =631/4 -> 157.75 | H3: =4527/4 -> 1131.75 | I3: =40/10 -> 4 | J3: =62/4 -> 15.5 | K3: =3/4 -> 0.75 | L3: =581/4 -> 145.25
A4: 300685 | B4: RB | C4: Isiah Pacheco | G4: =563/4 -> 140.75 | H4: =2442/4 -> 610.5 | I4: =18/4 -> 4.5 | J4: =47/4 -> 11.75 | K4: =1/4 -> 0.25 | L4: =249/4 -> 62.25
A5: 279792 | B5: RB | C5: Trestan Ebner | G5: =343/5 -> 68.6 | H5: =1690/5 -> 338 | I5: =9/5 -> 1.8 | J5: =127/5 -> 25.4 | K5: =11/5 -> 2.2 | L5: =1515/5 -> 303
A6: 300724 | B6: RB | C6: Keaontay Ingram | G6: =495/4 -> 123.75 | H6: =2722/4 -> 680.5 | I6: =16/4 -> 4 | J6: =89/4 -> 22.25 | K6: =6/4 -> 1.5 | L6: =671/4 -> 167.75
A7: 282443 | B7: RB | C7: Ty Chandler | G7: =603/5 -> 120.6 | H7: =3138/5 -> 627.6 | I7: =26/5 -> 5.2 | J7: =73/5 -> 14.6 | K7: =4/5 -> 0.8 | L7: =681/5 -> 136.2

Sheet WR
A1: college_gsis_id | B1: position | C1: player_name | D1: season | E1: team | F1: school_code | G1: receiving_receptions | H1: receiving_touchdowns | I1: receiving_yards | J1: kickreturns_avg | K1: kickreturns_long | L1: kickreturns_no | M1: kickreturns_touchdowns | N1: kickreturns_yards | O1: puntreturns_avg | P1: puntreturns_long | Q1: puntreturns_no | R1: puntreturns_td | S1: puntreturns_yds | T1: total_fumbles | U1: total_fumbles_lost
A2: 304745 | B2: WR | C2: Drake Stoops | G2: =IFERROR(AVERAGEIF('Full Player List'!$C$2:$C$1737, $C2, 'Full Player List'!P$2:P$1737),0) -> 27.333333 | H2: =IFERROR(AVERAGEIF('Full Player List'!$C$2:$C$1737, $C2, 'Full Player List'!Q$2:Q$1737),0) -> 2.8333333 | I2: =IFERROR(AVERAGEIF('Full Player List'!$C$2:$C$1737, $C2, 'Full Player List'!R$2:R$1737),0) -> 312.66667 | J2: =IFERROR(AVERAGEIF('Full Player List'!$C$2:$C$1737, $C2, 'Full Player List'!AA$2:AA$1737),0) -> 0 | K2: =IFERROR(AVERAGEIF('Full Player List'!$C$2:$C$1737, $C2, 'Full Player List'!AB$2:AB$1737),0) -> 0 | L2: =IFERROR(AVERAGEIF('Full Player List'!$C$2:$C$1737, $C2, 'Full Player List'!AC$2:AC$1737),0) -> 0 | M2: =IFERROR(AVERAGEIF('Full Player List'!$C$2:$C$1737, $C2, 'Full Player List'!AD$2:AD$1737),0) -> 0 | N2: =IFERROR(AVERAGEIF('Full Player List'!$C$2:$C$1737, $C2, 'Full Player List'!AE$2:AE$1737),0) -> 0 | O2: =IFERROR(AVERAGEIF('Full Player List'!$C$2:$C$1737, $C2, 'Full Player List'!AF$2:AF$1737),0) -> -1 | P2: =IFERROR(AVERAGEIF('Full Player List'!$C$2:$C$1737, $C2, 'Full Player List'!AG$2:AG$1737),0) -> -1 | Q2: =IFERROR(AVERAGEIF('Full Player List'!$C$2:$C$1737, $C2, 'Full Player List'!AH$2:AH$1737),0) -> 1 | ... V2: =IFERROR(AVERAGEIF('Full Player List'!$C$2:$C$1737, $C2, 'Full Player List'!AM$2:AM$1737),0) -> 0
A3: 309574 | B3: WR | C3: David White Jr. | G3: =IFERROR(AVERAGEIF('Full Player List'!$C$2:$C$1737, $C3, 'Full Player List'!P$2:P$1737),0) -> 27 | H3: =IFERROR(AVERAGEIF('Full Player List'!$C$2:$C$1737, $C3, 'Full Player List'!Q$2:Q$1737),0) -> 5.5 | I3: =IFERROR(AVERAGEIF('Full Player List'!$C$2:$C$1737, $C3, 'Full Player List'!R$2:R$1737),0) -> 451.5 | J3: =IFERROR(AVERAGEIF('Full Player List'!$C$2:$C$1737, $C3, 'Full Player List'!AA$2:AA$1737),0) -> 0 | K3: =IFERROR(AVERAGEIF('Full Player List'!$C$2:$C$1737, $C3, 'Full Player List'!AB$2:AB$1737),0) -> 0 | L3: =IFERROR(AVERAGEIF('Full Player List'!$C$2:$C$1737, $C3, 'Full Player List'!AC$2:AC$1737),0) -> 0 | M3: =IFERROR(AVERAGEIF('Full Player List'!$C$2:$C$1737, $C3, 'Full Player List'!AD$2:AD$1737),0) -> 0 | N3: =IFERROR(AVERAGEIF('Full Player List'!$C$2:$C$1737, $C3, 'Full Player List'!AE$2:AE$1737),0) -> 0 | O3: =IFERROR(AVERAGEIF('Full Player List'!$C$2:$C$1737, $C3, 'Full Player List'!AF$2:AF$1737),0) -> 0 | P3: =IFERROR(AVERAGEIF('Full Player List'!$C$2:$C$1737, $C3, 'Full Player List'!AG$2:AG$1737),0) -> 0 | Q3: =IFERROR(AVERAGEIF('Full Player List'!$C$2:$C$1737, $C3, 'Full Player List'!AH$2:AH$1737),0) -> 0 | ... V3: =IFERROR(AVERAGEIF('Full Player List'!$C$2:$C$1737, $C3, 'Full Player List'!AM$2:AM$1737),0) -> 0
A4: 325325 | B4: WR | C4: Cornelius Johnson | G4: =IFERROR(AVERAGEIF('Full Player List'!$C$2:$C$1737, $C4, 'Full Player List'!P$2:P$1737),0) -> 27.8 | H4: =IFERROR(AVERAGEIF('Full Player List'!$C$2:$C$1737, $C4, 'Full Player List'!Q$2:Q$1737),0) -> 2.8 | I4: =IFERROR(AVERAGEIF('Full Player List'!$C$2:$C$1737, $C4, 'Full Player List'!R$2:R$1737),0) -> 409 | J4: =IFERROR(AVERAGEIF('Full Player List'!$C$2:$C$1737, $C4, 'Full Player List'!AA$2:AA$1737),0) -> 0 | K4: =IFERROR(AVERAGEIF('Full Player List'!$C$2:$C$1737, $C4, 'Full Player List'!AB$2:AB$1737),0) -> 0 | L4: =IFERROR(AVERAGEIF('Full Player List'!$C$2:$C$1737, $C4, 'Full Player List'!AC$2:AC$1737),0) -> 0 | M4: =IFERROR(AVERAGEIF('Full Player List'!$C$2:$C$1737, $C4, 'Full Player List'!AD$2:AD$1737),0) -> 0 | N4: =IFERROR(AVERAGEIF('Full Player List'!$C$2:$C$1737, $C4, 'Full Player List'!AE$2:AE$1737),0) -> 0 | O4: =IFERROR(AVERAGEIF('Full Player List'!$C$2:$C$1737, $C4, 'Full Player List'!AF$2:AF$1737),0) -> 0 | P4: =IFERROR(AVERAGEIF('Full Player List'!$C$2:$C$1737, $C4, 'Full Player List'!AG$2:AG$1737),0) -> 0 | Q4: =IFERROR(AVERAGEIF('Full Player List'!$C$2:$C$1737, $C4, 'Full Player List'!AH$2:AH$1737),0) -> 0 | ... V4: =IFERROR(AVERAGEIF('Full Player List'!$C$2:$C$1737, $C4, 'Full Player List'!AM$2:AM$1737),0) -> 0
A5: 330388 | B5: WR | C5: Anthony Gould | G5: =IFERROR(AVERAGEIF('Full Player List'!$C$2:$C$1737, $C5, 'Full Player List'!P$2:P$1737),0) -> 28 | H5: =IFERROR(AVERAGEIF('Full Player List'!$C$2:$C$1737, $C5, 'Full Player List'!Q$2:Q$1737),0) -> 2 | I5: =IFERROR(AVERAGEIF('Full Player List'!$C$2:$C$1737, $C5, 'Full Player List'!R$2:R$1737),0) -> 453.33333 | J5: =IFERROR(AVERAGEIF('Full Player List'!$C$2:$C$1737, $C5, 'Full Player List'!AA$2:AA$1737),0) -> 0 | K5: =IFERROR(AVERAGEIF('Full Player List'!$C$2:$C$1737, $C5, 'Full Player List'!AB$2:AB$1737),0) -> 0 | L5: =IFERROR(AVERAGEIF('Full Player List'!$C$2:$C$1737, $C5, 'Full Player List'!AC$2:AC$1737),0) -> 0 | M5: =IFERROR(AVERAGEIF('Full Player List'!$C$2:$C$1737, $C5, 'Full Player List'!AD$2:AD$1737),0) -> 0 | N5: =IFERROR(AVERAGEIF('Full Player List'!$C$2:$C$1737, $C5, 'Full Player List'!AE$2:AE$1737),0) -> 0 | O5: =IFERROR(AVERAGEIF('Full Player List'!$C$2:$C$1737, $C5, 'Full Player List'!AF$2:AF$1737),0) -> 10.35 | P5: =IFERROR(AVERAGEIF('Full Player List'!$C$2:$C$1737, $C5, 'Full Player List'!AG$2:AG$1737),0) -> 33.5 | Q5: =IFERROR(AVERAGEIF('Full Player List'!$C$2:$C$1737, $C5, 'Full Player List'!AH$2:AH$1737),0) -> 6.25 | ... V5: =IFERROR(AVERAGEIF('Full Player List'!$C$2:$C$1737, $C5, 'Full Player List'!AM$2:AM$1737),0) -> 0
A6: 336471 | B6: WR | C6: Isaiah Williams | G6: =IFERROR(AVERAGEIF('Full Player List'!$C$2:$C$1737, $C6, 'Full Player List'!P$2:P$1737),0) -> 53.25 | H6: =IFERROR(AVERAGEIF('Full Player List'!$C$2:$C$1737, $C6, 'Full Player List'!Q$2:Q$1737),0) -> 3.5 | I6: =IFERROR(AVERAGEIF('Full Player List'!$C$2:$C$1737, $C6, 'Full Player List'!R$2:R$1737),0) -> 574.5 | J6: =IFERROR(AVERAGEIF('Full Player List'!$C$2:$C$1737, $C6, 'Full Player List'!AA$2:AA$1737),0) -> 0 | K6: =IFERROR(AVERAGEIF('Full Player List'!$C$2:$C$1737, $C6, 'Full Player List'!AB$2:AB$1737),0) -> 0 | L6: =IFERROR(AVERAGEIF('Full Player List'!$C$2:$C$1737, $C6, 'Full Player List'!AC$2:AC$1737),0) -> 0 | M6: =IFERROR(AVERAGEIF('Full Player List'!$C$2:$C$1737, $C6, 'Full Player List'!AD$2:AD$1737),0) -> 0 | N6: =IFERROR(AVERAGEIF('Full Player List'!$C$2:$C$1737, $C6, 'Full Player List'!AE$2:AE$1737),0) -> 0 | O6: =IFERROR(AVERAGEIF('Full Player List'!$C$2:$C$1737, $C6, 'Full Player List'!AF$2:AF$1737),0) -> 9.5 | P6: =IFERROR(AVERAGEIF('Full Player List'!$C$2:$C$1737, $C6, 'Full Player List'!AG$2:AG$1737),0) -> 27.5 | Q6: =IFERROR(AVERAGEIF('Full Player List'!$C$2:$C$1737, $C6, 'Full Player List'!AH$2:AH$1737),0) -> 13.5 | ... V6: =IFERROR(AVERAGEIF('Full Player List'!$C$2:$C$1737, $C6, 'Full Player List'!AM$2:AM$1737),0) -> 0
A7: 360413 | B7: WR | C7: Tejhaun Palmer | G7: =IFERROR(AVERAGEIF('Full Player List'!$C$2:$C$1737, $C7, 'Full Player List'!P$2:P$1737),0) -> 27.666667 | H7: =IFERROR(AVERAGEIF('Full Player List'!$C$2:$C$1737, $C7, 'Full Player List'!Q$2:Q$1737),0) -> 3 | I7: =IFERROR(AVERAGEIF('Full Player List'!$C$2:$C$1737, $C7, 'Full Player List'!R$2:R$1737),0) -> 469.66667 | J7: =IFERROR(AVERAGEIF('Full Player List'!$C$2:$C$1737, $C7, 'Full Player List'!AA$2:AA$1737),0) -> 0 | K7: =IFERROR(AVERAGEIF('Full Player List'!$C$2:$C$1737, $C7, 'Full Player List'!AB$2:AB$1737),0) -> 0 | L7: =IFERROR(AVERAGEIF('Full Player List'!$C$2:$C$1737, $C7, 'Full Player List'!AC$2:AC$1737),0) -> 0 | M7: =IFERROR(AVERAGEIF('Full Player List'!$C$2:$C$1737, $C7, 'Full Player List'!AD$2:AD$1737),0) -> 0 | N7: =IFERROR(AVERAGEIF('Full Player List'!$C$2:$C$1737, $C7, 'Full Player List'!AE$2:AE$1737),0) -> 0 | O7: =IFERROR(AVERAGEIF('Full Player List'!$C$2:$C$1737, $C7, 'Full Player List'!AF$2:AF$1737),0) -> 0 | P7: =IFERROR(AVERAGEIF('Full Player List'!$C$2:$C$1737, $C7, 'Full Player List'!AG$2:AG$1737),0) -> 0 | Q7: =IFERROR(AVERAGEIF('Full Player List'!$C$2:$C$1737, $C7, 'Full Player List'!AH$2:AH$1737),0) -> 0 | ... V7: =IFERROR(AVERAGEIF('Full Player List'!$C$2:$C$1737, $C7, 'Full Player List'!AM$2:AM$1737),0) -> 0
A8: 326531 | B8: WR | C8: Casey Washington | G8: =IFERROR(AVERAGEIF('Full Player List'!$C$2:$C$1737, $C8, 'Full Player List'!P$2:P$1737),0) -> 24.4 | H8: =IFERROR(AVERAGEIF('Full Player List'!$C$2:$C$1737, $C8, 'Full Player List'!Q$2:Q$1737),0) -> 0.8 | I8: =IFERROR(AVERAGEIF('Full Player List'!$C$2:$C$1737, $C8, 'Full Player List'!R$2:R$1737),0) -> 299.4 | J8: =IFERROR(AVERAGEIF('Full Player List'!$C$2:$C$1737, $C8, 'Full Player List'!AA$2:AA$1737),0) -> 0 | K8: =IFERROR(AVERAGEIF('Full Player List'!$C$2:$C$1737, $C8, 'Full Player List'!AB$2:AB$1737),0) -> 0 | L8: =IFERROR(AVERAGEIF('Full Player List'!$C$2:$C$1737, $C8, 'Full Player List'!AC$2:AC$1737),0) -> 0 | M8: =IFERROR(AVERAGEIF('Full Player List'!$C$2:$C$1737, $C8, 'Full Player List'!AD$2:AD$1737),0) -> 0 | N8: =IFERROR(AVERAGEIF('Full Player List'!$C$2:$C$1737, $C8, 'Full Player List'!AE$2:AE$1737),0) -> 0 | O8: =IFERROR(AVERAGEIF('Full Player List'!$C$2:$C$1737, $C8, 'Full Player List'!AF$2:AF$1737),0) -> 0 | P8: =IFERROR(AVERAGEIF('Full Player List'!$C$2:$C$1737, $C8, 'Full Player List'!AG$2:AG$1737),0) -> 0 | Q8: =IFERROR(AVERAGEIF('Full Player List'!$C$2:$C$1737, $C8, 'Full Player List'!AH$2:AH$1737),0) -> 0 | ... V8: =IFERROR(AVERAGEIF('Full Player List'!$C$2:$C$1737, $C8, 'Full Player List'!AM$2:AM$1737),0) -> 0
A9: 314613 | B9: WR | C9: Jaxon Janke | G9: =IFERROR(AVERAGEIF('Full Player List'!$C$2:$C$1737, $C9, 'Full Player List'!P$2:P$1737),0) -> 26 | H9: =IFERROR(AVERAGEIF('Full Player List'!$C$2:$C$1737, $C9, 'Full Player List'!Q$2:Q$1737),0) -> 3.25 | I9: =IFERROR(AVERAGEIF('Full Player List'!$C$2:$C$1737, $C9, 'Full Player List'!R$2:R$1737),0) -> 398 | J9: =IFERROR(AVERAGEIF('Full Player List'!$C$2:$C$1737, $C9, 'Full Player List'!AA$2:AA$1737),0) -> 0 | K9: =IFERROR(AVERAGEIF('Full Player List'!$C$2:$C$1737, $C9, 'Full Player List'!AB$2:AB$1737),0) -> 0 | L9: =IFERROR(AVERAGEIF('Full Player List'!$C$2:$C$1737, $C9, 'Full Player List'!AC$2:AC$1737),0) -> 0 | M9: =IFERROR(AVERAGEIF('Full Player List'!$C$2:$C$1737, $C9, 'Full Player List'!AD$2:AD$1737),0) -> 0 | N9: =IFERROR(AVERAGEIF('Full Player List'!$C$2:$C$1737, $C9, 'Full Player List'!AE$2:AE$1737),0) -> 0 | O9: =IFERROR(AVERAGEIF('Full Player List'!$C$2:$C$1737, $C9, 'Full Player List'!AF$2:AF$1737),0) -> 8 | P9: =IFERROR(AVERAGEIF('Full Player List'!$C$2:$C$1737, $C9, 'Full Player List'!AG$2:AG$1737),0) -> 8 | Q9: =IFERROR(AVERAGEIF('Full Player List'!$C$2:$C$1737, $C9, 'Full Player List'!AH$2:AH$1737),0) -> 1 | ... V9: =IFERROR(AVERAGEIF('Full Player List'!$C$2:$C$1737, $C9, 'Full Player List'!AM$2:AM$1737),0) -> 0
A10: 317480 | B10: WR | C10: Jadon Janke | G10: =IFERROR(AVERAGEIF('Full Player List'!$C$2:$C$1737, $C10, 'Full Player List'!P$2:P$1737),0) -> 35.666667 | H10: =IFERROR(AVERAGEIF('Full Player List'!$C$2:$C$1737, $C10, 'Full Player List'!Q$2:Q$1737),0) -> 5.6666667 | I10: =IFERROR(AVERAGEIF('Full Player List'!$C$2:$C$1737, $C10, 'Full Player List'!R$2:R$1737),0) -> 576.33333 | J10: =IFERROR(AVERAGEIF('Full Player List'!$C$2:$C$1737, $C10, 'Full Player List'!AA$2:AA$1737),0) -> 7.9 | K10: =IFERROR(AVERAGEIF('Full Player List'!$C$2:$C$1737, $C10, 'Full Player List'!AB$2:AB$1737),0) -> 14 | L10: =IFERROR(AVERAGEIF('Full Player List'!$C$2:$C$1737, $C10, 'Full Player List'!AC$2:AC$1737),0) -> 4.5 | M10: =IFERROR(AVERAGEIF('Full Player List'!$C$2:$C$1737, $C10, 'Full Player List'!AD$2:AD$1737),0) -> 0 | N10: =IFERROR(AVERAGEIF('Full Player List'!$C$2:$C$1737, $C10, 'Full Player List'!AE$2:AE$1737),0) -> 70 | O10: =IFERROR(AVERAGEIF('Full Player List'!$C$2:$C$1737, $C10, 'Full Player List'!AF$2:AF$1737),0) -> 13.2 | P10: =IFERROR(AVERAGEIF('Full Player List'!$C$2:$C$1737, $C10, 'Full Player List'!AG$2:AG$1737),0) -> 58 | Q10: =IFERROR(AVERAGEIF('Full Player List'!$C$2:$C$1737, $C10, 'Full Player List'!AH$2:AH$1737),0) -> 12 | ... V10: =IFERROR(AVERAGEIF('Full Player List'!$C$2:$C$1737, $C10, 'Full Player List'!AM$2:AM$1737),0) -> 0
A11: 325538 | B11: WR | C11: Joshua Cephus | G11: =IFERROR(AVERAGEIF('Full Player List'!$C$2:$C$1737, $C11, 'Full Player List'!P$2:P$1737),0) -> 62.6 | H11: =IFERROR(AVERAGEIF('Full Player List'!$C$2:$C$1737, $C11, 'Full Player List'!Q$2:Q$1737),0) -> 5.6 | I11: =IFERROR(AVERAGEIF('Full Player List'!$C$2:$C$1737, $C11, 'Full Player List'!R$2:R$1737),0) -> 727.8 | J11: =IFERROR(AVERAGEIF('Full Player List'!$C$2:$C$1737, $C11, 'Full Player List'!AA$2:AA$1737),0) -> 12 | K11: =IFERROR(AVERAGEIF('Full Player List'!$C$2:$C$1737, $C11, 'Full Player List'!AB$2:AB$1737),0) -> 12 | L11: =IFERROR(AVERAGEIF('Full Player List'!$C$2:$C$1737, $C11, 'Full Player List'!AC$2:AC$1737),0) -> 1 | M11: =IFERROR(AVERAGEIF('Full Player List'!$C$2:$C$1737, $C11, 'Full Player List'!AD$2:AD$1737),0) -> 0 | N11: =IFERROR(AVERAGEIF('Full Player List'!$C$2:$C$1737, $C11, 'Full Player List'!AE$2:AE$1737),0) -> 12 | O11: =IFERROR(AVERAGEIF('Full Player List'!$C$2:$C$1737, $C11, 'Full Player List'!AF$2:AF$1737),0) -> 10 | P11: =IFERROR(AVERAGEIF('Full Player List'!$C$2:$C$1737, $C11, 'Full Player List'!AG$2:AG$1737),0) -> 16.5 | Q11: =IFERROR(AVERAGEIF('Full Player List'!$C$2:$C$1737, $C11, 'Full Player List'!AH$2:AH$1737),0) -> 5 | ... V11: =IFERROR(AVERAGEIF('Full Player List'!$C$2:$C$1737, $C11, 'Full Player List'!AM$2:AM$1737),0) -> 0
A12: 325753 | B12: WR | C12: Jerrod Means | G12: =IFERROR(AVERAGEIF('Full Player List'!$C$2:$C$1737, $C12, 'Full Player List'!P$2:P$1737),0) -> 30 | H12: =IFERROR(AVERAGEIF('Full Player List'!$C$2:$C$1737, $C12, 'Full Player List'!Q$2:Q$1737),0) -> 3.3333333 | I12: =IFERROR(AVERAGEIF('Full Player List'!$C$2:$C$1737, $C12, 'Full Player List'!R$2:R$1737),0) -> 517.33333 | J12: =IFERROR(AVERAGEIF('Full Player List'!$C$2:$C$1737, $C12, 'Full Player List'!AA$2:AA$1737),0) -> 20.3 | K12: =IFERROR(AVERAGEIF('Full Player List'!$C$2:$C$1737, $C12, 'Full Player List'!AB$2:AB$1737),0) -> 27 | L12: =IFERROR(AVERAGEIF('Full Player List'!$C$2:$C$1737, $C12, 'Full Player List'!AC$2:AC$1737),0) -> 12 | M12: =IFERROR(AVERAGEIF('Full Player List'!$C$2:$C$1737, $C12, 'Full Player List'!AD$2:AD$1737),0) -> 0 | N12: =IFERROR(AVERAGEIF('Full Player List'!$C$2:$C$1737, $C12, 'Full Player List'!AE$2:AE$1737),0) -> 244 | O12: =IFERROR(AVERAGEIF('Full Player List'!$C$2:$C$1737, $C12, 'Full Player List'!AF$2:AF$1737),0) -> 0 | P12: =IFERROR(AVERAGEIF('Full Player List'!$C$2:$C$1737, $C12, 'Full Player List'!AG$2:AG$1737),0) -> 0 | Q12: =IFERROR(AVERAGEIF('Full Player List'!$C$2:$C$1737, $C12, 'Full Player List'!AH$2:AH$1737),0) -> 0 | ... V12: =IFERROR(AVERAGEIF('Full Player List'!$C$2:$C$1737, $C12, 'Full Player List'!AM$2:AM$1737),0) -> 0
A13: 327751 | B13: WR | C13: Tahj Washington | G13: =IFERROR(AVERAGEIF('Full Player List'!$C$2:$C$1737, $C13, 'Full Player List'!P$2:P$1737),0) -> 41.8 | H13: =IFERROR(AVERAGEIF('Full Player List'!$C$2:$C$1737, $C13, 'Full Player List'!Q$2:Q$1737),0) -> 4.2 | I13: =IFERROR(AVERAGEIF('Full Player List'!$C$2:$C$1737, $C13, 'Full Player List'!R$2:R$1737),0) -> 644.8 | J13: =IFERROR(AVERAGEIF('Full Player List'!$C$2:$C$1737, $C13, 'Full Player List'!AA$2:AA$1737),0) -> 20.833333 | K13: =IFERROR(AVERAGEIF('Full Player List'!$C$2:$C$1737, $C13, 'Full Player List'!AB$2:AB$1737),0) -> 32.666667 | L13: =IFERROR(AVERAGEIF('Full Player List'!$C$2:$C$1737, $C13, 'Full Player List'!AC$2:AC$1737),0) -> 7.3333333 | M13: =IFERROR(AVERAGEIF('Full Player List'!$C$2:$C$1737, $C13, 'Full Player List'!AD$2:AD$1737),0) -> 0 | N13: =IFERROR(AVERAGEIF('Full Player List'!$C$2:$C$1737, $C13, 'Full Player List'!AE$2:AE$1737),0) -> 146 | O13: =IFERROR(AVERAGEIF('Full Player List'!$C$2:$C$1737, $C13, 'Full Player List'!AF$2:AF$1737),0) -> 0 | P13: =IFERROR(AVERAGEIF('Full Player List'!$C$2:$C$1737, $C13, 'Full Player List'!AG$2:AG$1737),0) -> 0 | Q13: =IFERROR(AVERAGEIF('Full Player List'!$C$2:$C$1737, $C13, 'Full Player List'!AH$2:AH$1737),0) -> 0 | ... V13: =IFERROR(AVERAGEIF('Full Player List'!$C$2:$C$1737, $C13, 'Full Player List'!AM$2:AM$1737),0) -> 0
... A28: 350271 | B28: WR | C28: Keandre Lambert | G28: =IFERROR(AVERAGEIF('Full Player List'!$C$2:$C$1737, $C28, 'Full Player List'!P$2:P$1737),0) -> 35 | H28: =IFERROR(AVERAGEIF('Full Player List'!$C$2:$C$1737, $C28, 'Full Player List'!Q$2:Q$1737),0) -> 3.8 | I28: =IFERROR(AVERAGEIF('Full Player List'!$C$2:$C$1737, $C28, 'Full Player List'!R$2:R$1737),0) -> 539.2 | J28: =IFERROR(AVERAGEIF('Full Player List'!$C$2:$C$1737, $C28, 'Full Player List'!AA$2:AA$1737),0) -> 0 | K28: =IFERROR(AVERAGEIF('Full Player List'!$C$2:$C$1737, $C28, 'Full Player List'!AB$2:AB$1737),0) -> 0 | L28: =IFERROR(AVERAGEIF('Full Player List'!$C$2:$C$1737, $C28, 'Full Player List'!AC$2:AC$1737),0) -> 0 | M28: =IFERROR(AVERAGEIF('Full Player List'!$C$2:$C$1737, $C28, 'Full Player List'!AD$2:AD$1737),0) -> 0 | N28: =IFERROR(AVERAGEIF('Full Player List'!$C$2:$C$1737, $C28, 'Full Player List'!AE$2:AE$1737),0) -> 0 | O28: =IFERROR(AVERAGEIF('Full Player List'!$C$2:$C$1737, $C28, 'Full Player List'!AF$2:AF$1737),0) -> 0 | P28: =IFERROR(AVERAGEIF('Full Player List'!$C$2:$C$1737, $C28, 'Full Player List'!AG$2:AG$1737),0) -> 0 | Q28: =IFERROR(AVERAGEIF('Full Player List'!$C$2:$C$1737, $C28, 'Full Player List'!AH$2:AH$1737),0) -> 0 | ... V28: =IFERROR(AVERAGEIF('Full Player List'!$C$2:$C$1737, $C28, 'Full Player List'!AM$2:AM$1737),0) -> 0

Sheet TE
A1: college_gsis_id | B1: position | C1: player_name | D1: season | E1: team | F1: school_code | G1: receiving_receptions | H1: receiving_touchdowns | I1: receiving_yards | J1: total_fumbles | K1: total_fumbles_lost
A2: 325932 | B2: TE | C2: Joshua Simon | G2: =IFERROR(AVERAGEIF('Full Player List'!$C$2:$C$1737,$C2,'Full Player List'!P$2:P$1737),0) -> 25.833333 | H2: =IFERROR(AVERAGEIF('Full Player List'!$C$2:$C$1737,$C2,'Full Player List'!Q$2:Q$1737),0) -> 4.1666667 | I2: =IFERROR(AVERAGEIF('Full Player List'!$C$2:$C$1737,$C2,'Full Player List'!R$2:R$1737),0) -> 319 | J2: =IFERROR(AVERAGEIF('Full Player List'!$C$2:$C$1737,$C2,'Full Player List'!AK$2:AK$1737),0) -> 1.6666667 | K2: =IFERROR(AVERAGEIF('Full Player List'!$C$2:$C$1737,$C2,'Full Player List'!AL$2:AL$1737),0) -> 0.66666667 | L2: =IFERROR(AVERAGEIF('Full Player List'!$C$2:$C$1737,$C2,'Full Player List'!AM$2:AM$1737),0) -> 0
A3: 349235 | B3: TE | C3: Rivaldo Fairweather | G3: =IFERROR(AVERAGEIF('Full Player List'!$C$2:$C$1737,$C3,'Full Player List'!P$2:P$1737),0) -> 24.4 | H3: =IFERROR(AVERAGEIF('Full Player List'!$C$2:$C$1737,$C3,'Full Player List'!Q$2:Q$1737),0) -> 2.4 | I3: =IFERROR(AVERAGEIF('Full Player List'!$C$2:$C$1737,$C3,'Full Player List'!R$2:R$1737),0) -> 307.4 | J3: =IFERROR(AVERAGEIF('Full Player List'!$C$2:$C$1737,$C3,'Full Player List'!AK$2:AK$1737),0) -> 1 | K3: =IFERROR(AVERAGEIF('Full Player List'!$C$2:$C$1737,$C3,'Full Player List'!AL$2:AL$1737),0) -> 1 | L3: =IFERROR(AVERAGEIF('Full Player List'!$C$2:$C$1737,$C3,'Full Player List'!AM$2:AM$1737),0) -> 0
A4: 351068 | B4: TE | C4: Luke Lachey | G4: =IFERROR(AVERAGEIF('Full Player List'!$C$2:$C$1737,$C4,'Full Player List'!P$2:P$1737),0) -> 18.5 | H4: =IFERROR(AVERAGEIF('Full Player List'!$C$2:$C$1737,$C4,'Full Player List'!Q$2:Q$1737),0) -> 1 | I4: =IFERROR(AVERAGEIF('Full Player List'!$C$2:$C$1737,$C4,'Full Player List'!R$2:R$1737),0) -> 223.25 | J4: =IFERROR(AVERAGEIF('Full Player List'!$C$2:$C$1737,$C4,'Full Player List'!AK$2:AK$1737),0) -> 1 | K4: =IFERROR(AVERAGEIF('Full Player List'!$C$2:$C$1737,$C4,'Full Player List'!AL$2:AL$1737),0) -> 0 | L4: =IFERROR(AVERAGEIF('Full Player List'!$C$2:$C$1737,$C4,'Full Player List'!AM$2:AM$1737),0) -> 0
A5: 351662 | B5: TE | C5: Caden Prieskorn | G5: =IFERROR(AVERAGEIF('Full Player List'!$C$2:$C$1737,$C5,'Full Player List'!P$2:P$1737),0) -> 22.4 | H5: =IFERROR(AVERAGEIF('Full Player List'!$C$2:$C$1737,$C5,'Full Player List'!Q$2:Q$1737),0) -> 2.8 | I5: =IFERROR(AVERAGEIF('Full Player List'!$C$2:$C$1737,$C5,'Full Player List'!R$2:R$1737),0) -> 306.2 | J5: =IFERROR(AVERAGEIF('Full Player List'!$C$2:$C$1737,$C5,'Full Player List'!AK$2:AK$1737),0) -> 1 | K5: =IFERROR(AVERAGEIF('Full Player List'!$C$2:$C$1737,$C5,'Full Player List'!AL$2:AL$1737),0) -> 1 | L5: =IFERROR(AVERAGEIF('Full Player List'!$C$2:$C$1737,$C5,'Full Player List'!AM$2:AM$1737),0) -> 0
A6: 326147 | B6: TE | C6: Zach Heins | G6: =IFERROR(AVERAGEIF('Full Player List'!$C$2:$C$1737,$C6,'Full Player List'!P$2:P$1737),0) -> 17 | H6: =IFERROR(AVERAGEIF('Full Player List'!$C$2:$C$1737,$C6,'Full Player List'!Q$2:Q$1737),0) -> 4 | I6: =IFERROR(AVERAGEIF('Full Player List'!$C$2:$C$1737,$C6,'Full Player List'!R$2:R$1737),0) -> 237.66667 | J6: =IFERROR(AVERAGEIF('Full Player List'!$C$2:$C$1737,$C6,'Full Player List'!AK$2:AK$1737),0) -> 2 | K6: =IFERROR(AVERAGEIF('Full Player List'!$C$2:$C$1737,$C6,'Full Player List'!AL$2:AL$1737),0) -> 2 | L6: =IFERROR(AVERAGEIF('Full Player List'!$C$2:$C$1737,$C6,'Full Player List'!AM$2:AM$1737),0) -> 0
A7: 326564 | B7: TE | C7: Mason Fairchild | G7: =IFERROR(AVERAGEIF('Full Player List'!$C$2:$C$1737,$C7,'Full Player List'!P$2:P$1737),0) -> 16.4 | H7: =IFERROR(AVERAGEIF('Full Player List'!$C$2:$C$1737,$C7,'Full Player List'!Q$2:Q$1737),0) -> 2 | I7: =IFERROR(AVERAGEIF('Full Player List'!$C$2:$C$1737,$C7,'Full Player List'!R$2:R$1737),0) -> 222.2 | J7: =IFERROR(AVERAGEIF('Full Player List'!$C$2:$C$1737,$C7,'Full Player List'!AK$2:AK$1737),0) -> 0 | K7: =IFERROR(AVERAGEIF('Full Player List'!$C$2:$C$1737,$C7,'Full Player List'!AL$2:AL$1737),0) -> 0 | L7: =IFERROR(AVERAGEIF('Full Player List'!$C$2:$C$1737,$C7,'Full Player List'!AM$2:AM$1737),0) -> 0
A8: 339883 | B8: TE | C8: Isaac Rex | G8: =IFERROR(AVERAGEIF('Full Player List'!$C$2:$C$1737,$C8,'Full Player List'!P$2:P$1737),0) -> 22.4 | H8: =IFERROR(AVERAGEIF('Full Player List'!$C$2:$C$1737,$C8,'Full Player List'!Q$2:Q$1737),0) -> 4.8 | I8: =IFERROR(AVERAGEIF('Full Player List'!$C$2:$C$1737,$C8,'Full Player List'!R$2:R$1737),0) -> 277 | J8: =IFERROR(AVERAGEIF('Full Player List'!$C$2:$C$1737,$C8,'Full Player List'!AK$2:AK$1737),0) -> 1 | K8: =IFERROR(AVERAGEIF('Full Player List'!$C$2:$C$1737,$C8,'Full Player List'!AL$2:AL$1737),0) -> 1 | L8: =IFERROR(AVERAGEIF('Full Player List'!$C$2:$C$1737,$C8,'Full Player List'!AM$2:AM$1737),0) -> 0
A9: 300511 | B9: TE | C9: Dallin Holker | G9: =IFERROR(AVERAGEIF('Full Player List'!$C$2:$C$1737,$C9,'Full Player List'!P$2:P$1737),0) -> 26.5 | H9: =IFERROR(AVERAGEIF('Full Player List'!$C$2:$C$1737,$C9,'Full Player List'!Q$2:Q$1737),0) -> 2.25 | I9: =IFERROR(AVERAGEIF('Full Player List'!$C$2:$C$1737,$C9,'Full Player List'!R$2:R$1737),0) -> 322 | J9: =IFERROR(AVERAGEIF('Full Player List'!$C$2:$C$1737,$C9,'Full Player List'!AK$2:AK$1737),0) -> 1.5 | K9: =IFERROR(AVERAGEIF('Full Player List'!$C$2:$C$1737,$C9,'Full Player List'!AL$2:AL$1737),0) -> 1.5 | L9: =IFERROR(AVERAGEIF('Full Player List'!$C$2:$C$1737,$C9,'Full Player List'!AM$2:AM$1737),0) -> 0
A10: 314829 | B10: TE | C10: McCallan Castles | G10: =IFERROR(AVERAGEIF('Full Player List'!$C$2:$C$1737,$C10,'Full Player List'!P$2:P$1737),0) -> 14.25 | H10: =IFERROR(AVERAGEIF('Full Player List'!$C$2:$C$1737,$C10,'Full Player List'!Q$2:Q$1737),0) -> 2 | I10: =IFERROR(AVERAGEIF('Full Player List'!$C$2:$C$1737,$C10,'Full Player List'!R$2:R$1737),0) -> 172.25 | J10: =IFERROR(AVERAGEIF('Full Player List'!$C$2:$C$1737,$C10,'Full Player List'!AK$2:AK$1737),0) -> 0 | K10: =IFERROR(AVERAGEIF('Full Player List'!$C$2:$C$1737,$C10,'Full Player List'!AL$2:AL$1737),0) -> 0 | L10: =IFERROR(AVERAGEIF('Full Player List'!$C$2:$C$1737,$C10,'Full Player List'!AM$2:AM$1737),0) -> 0
A11: 350636 | B11: TE | C11: Tip Reiman | G11: =IFERROR(AVERAGEIF('Full Player List'!$C$2:$C$1737,$C11,'Full Player List'!P$2:P$1737),0) -> 13.666667 | H11: =IFERROR(AVERAGEIF('Full Player List'!$C$2:$C$1737,$C11,'Full Player List'!Q$2:Q$1737),0) -> 1.6666667 | I11: =IFERROR(AVERAGEIF('Full Player List'!$C$2:$C$1737,$C11,'Full Player List'!R$2:R$1737),0) -> 139.66667 | J11: =IFERROR(AVERAGEIF('Full Player List'!$C$2:$C$1737,$C11,'Full Player List'!AK$2:AK$1737),0) -> 0 | K11: =IFERROR(AVERAGEIF('Full Player List'!$C$2:$C$1737,$C11,'Full Player List'!AL$2:AL$1737),0) -> 0 | L11: =IFERROR(AVERAGEIF('Full Player List'!$C$2:$C$1737,$C11,'Full Player List'!AM$2:AM$1737),0) -> 0
A12: 311444 | B12: TE | C12: Cam Grandy | G12: =IFERROR(AVERAGEIF('Full Player List'!$C$2:$C$1737,$C12,'Full Player List'!P$2:P$1737),0) -> 30 | H12: =IFERROR(AVERAGEIF('Full Player List'!$C$2:$C$1737,$C12,'Full Player List'!Q$2:Q$1737),0) -> 2.25 | I12: =IFERROR(AVERAGEIF('Full Player List'!$C$2:$C$1737,$C12,'Full Player List'!R$2:R$1737),0) -> 303.25 | J12: =IFERROR(AVERAGEIF('Full Player List'!$C$2:$C$1737,$C12,'Full Player List'!AK$2:AK$1737),0) -> 0 | K12: =IFERROR(AVERAGEIF('Full Player List'!$C$2:$C$1737,$C12,'Full Player List'!AL$2:AL$1737),0) -> 0 | L12: =IFERROR(AVERAGEIF('Full Player List'!$C$2:$C$1737,$C12,'Full Player List'!AM$2:AM$1737),0) -> 0

Sheet OL
A1: college_gsis_id | B1: position | C1: player_name | D1: season | E1: team | F1: school_code
A2: 312931 | B2: OT | C2: Julian Pearl | D2: 2023 | E2: Illinois | F2: ILUN
A3: 325463 | B3: OT | C3: Walter Rouse | D3: 2023 | E3: Oklahoma | F3: OKUN
A4: 327296 | B4: OT | C4: Tylan Grable | D4: 2023 | E4: UCF | F4: FLCE
A5: 327928 | B5: OT | C5: Xavier Truss | D5: 2023 | E5: Georgia | F5: GAUN
A6: 350535 | B6: OT | C6: Bryce Cabledue | D6: 2023 | E6: Kansas | F6: KSUN
A7: 350683 | B7: OT | C7: Brandon Crenshaw-Dickson | D7: 2024 | E7: Florida | F7: FLUN
A8: 350170 | B8: OC | C8: Gus Hartwig | D8: 2024 | E8: Purdue | F8: INPU
A9: 351261 | B9: OG | C9: Joshua Gray | D9: 2024 | E9: Oregon State | F9: ORST
A10: 354742 | B10: OG | C10: Luke Newman | D10: 2024 | E10: Michigan State | F10: MIST
A11: 368279 | B11: OG | C11: Joe Huber | D11: 2024 | E11: Wisconsin | F11: WIUN
A12: 373841 | B12: OG | C12: Gareth Warren | D12: 2024 | E12: Lindenwood | F12: MOLW
A13: 337857 | B13: OG | C13: Willis Patrick | D13: 2023 | E13: TCU | F13: TXCU
... A25: 326095 | B25: OC | C25: Dylan McMahon | D25: 2023 | E25: NC State | F25: NCST

Sheet DT
A1: college_gsis_id | B1: position | C1: player_name | D1: season | E1: team | F1: school_code | G1: defense_pass_breakups | H1: defense_qb_hurries | I1: defense_sacks | J1: defense_solo_tackles | K1: defense_total_tackles | L1: defense_tackles_for_loss | M1: defense_interceptions | N1: defense_touchdowns
A2: 330326 | B2: DT | C2: Jared Harrison-Hunte | D2: 2023 | G2: =IFERROR(AVERAGEIF('Full Player List'!$C$2:$C$1737, $C2, 'Full Player List'!S$2:S$1737),0) -> 0.2 | H2: =IFERROR(AVERAGEIF('Full Player List'!$C$2:$C$1737, $C2, 'Full Player List'!T$2:T$1737),0) -> 2.4 | I2: =IFERROR(AVERAGEIF('Full Player List'!$C$2:$C$1737, $C2, 'Full Player List'!U$2:U$1737),0) -> 3.1 | J2: =IFERROR(AVERAGEIF('Full Player List'!$C$2:$C$1737, $C2, 'Full Player List'!V$2:V$1737),0) -> 11.4 | K2: =IFERROR(AVERAGEIF('Full Player List'!$C$2:$C$1737, $C2, 'Full Player List'!W$2:W$1737),0) -> 23 | L2: =IFERROR(AVERAGEIF('Full Player List'!$C$2:$C$1737, $C2, 'Full Player List'!X$2:X$1737),0) -> 5.2 | M2: =IFERROR(AVERAGEIF('Full Player List'!$C$2:$C$1737, $C2, 'Full Player List'!Y$2:Y$1737),0) -> 1 | N2: =IFERROR(AVERAGEIF('Full Player List'!$C$2:$C$1737, $C2, 'Full Player List'!Z$2:Z$1737),0) -> 0
A3: 348705 | B3: DT | C3: Cameron Horsley | D3: 2023 | G3: =IFERROR(AVERAGEIF('Full Player List'!$C$2:$C$1737, $C3, 'Full Player List'!S$2:S$1737),0) -> 1.6 | H3: =IFERROR(AVERAGEIF('Full Player List'!$C$2:$C$1737, $C3, 'Full Player List'!T$2:T$1737),0) -> 2.4 | I3: =IFERROR(AVERAGEIF('Full Player List'!$C$2:$C$1737, $C3, 'Full Player List'!U$2:U$1737),0) -> 0.8 | J3: =IFERROR(AVERAGEIF('Full Player List'!$C$2:$C$1737, $C3, 'Full Player List'!V$2:V$1737),0) -> 15.4 | K3: =IFERROR(AVERAGEIF('Full Player List'!$C$2:$C$1737, $C3, 'Full Player List'!W$2:W$1737),0) -> 33.2 | L3: =IFERROR(AVERAGEIF('Full Player List'!$C$2:$C$1737, $C3, 'Full Player List'!X$2:X$1737),0) -> 4.1 | M3: =IFERROR(AVERAGEIF('Full Player List'!$C$2:$C$1737, $C3, 'Full Player List'!Y$2:Y$1737),0) -> 0 | N3: =IFERROR(AVERAGEIF('Full Player List'!$C$2:$C$1737, $C3, 'Full Player List'!Z$2:Z$1737),0) -> 0
A4: 349011 | B4: DT | C4: Tonka Hemingway | D4: 2023 | G4: =IFERROR(AVERAGEIF('Full Player List'!$C$2:$C$1737, $C4, 'Full Player List'!S$2:S$1737),0) -> 2.2 | H4: =IFERROR(AVERAGEIF('Full Player List'!$C$2:$C$1737, $C4, 'Full Player List'!T$2:T$1737),0) -> 3.4 | I4: =IFERROR(AVERAGEIF('Full Player List'!$C$2:$C$1737, $C4, 'Full Player List'!U$2:U$1737),0) -> 1.9 | J4: =IFERROR(AVERAGEIF('Full Player List'!$C$2:$C$1737, $C4, 'Full Player List'!V$2:V$1737),0) -> 13.6 | K4: =IFERROR(AVERAGEIF('Full Player List'!$C$2:$C$1737, $C4, 'Full Player List'!W$2:W$1737),0) -> 21.6 | L4: =IFERROR(AVERAGEIF('Full Player List'!$C$2:$C$1737, $C4, 'Full Player List'!X$2:X$1737),0) -> 3.3 | M4: =IFERROR(AVERAGEIF('Full Player List'!$C$2:$C$1737, $C4, 'Full Player List'!Y$2:Y$1737),0) -> 0 | N4: =IFERROR(AVERAGEIF('Full Player List'!$C$2:$C$1737, $C4, 'Full Player List'!Z$2:Z$1737),0) -> 0
A5: 349254 | B5: DT | C5: J.J. Pegues | D5: 2023 | G5: =IFERROR(AVERAGEIF('Full Player List'!$C$2:$C$1737, $C5, 'Full Player List'!S$2:S$1737),0) -> 1 | H5: =IFERROR(AVERAGEIF('Full Player List'!$C$2:$C$1737, $C5, 'Full Player List'!T$2:T$1737),0) -> 2.5 | I5: =IFERROR(AVERAGEIF('Full Player List'!$C$2:$C$1737, $C5, 'Full Player List'!U$2:U$1737),0) -> 2.5 | J5: =IFERROR(AVERAGEIF('Full Player List'!$C$2:$C$1737, $C5, 'Full Player List'!V$2:V$1737),0) -> 15.25 | K5: =IFERROR(AVERAGEIF('Full Player List'!$C$2:$C$1737, $C5, 'Full Player List'!W$2:W$1737),0) -> 31.25 | L5: =IFERROR(AVERAGEIF('Full Player List'!$C$2:$C$1737, $C5, 'Full Player List'!X$2:X$1737),0) -> 6.875 | M5: =IFERROR(AVERAGEIF('Full Player List'!$C$2:$C$1737, $C5, 'Full Player List'!Y$2:Y$1737),0) -> 0 | N5: =IFERROR(AVERAGEIF('Full Player List'!$C$2:$C$1737, $C5, 'Full Player List'!Z$2:Z$1737),0) -> 0
A6: 349905 | B6: DT | C6: Nazir Stackhouse | D6: 2023 | G6: =IFERROR(AVERAGEIF('Full Player List'!$C$2:$C$1737, $C6, 'Full Player List'!S$2:S$1737),0) -> 0.4 | H6: =IFERROR(AVERAGEIF('Full Player List'!$C$2:$C$1737, $C6, 'Full Player List'!T$2:T$1737),0) -> 0.2 | I6: =IFERROR(AVERAGEIF('Full Player List'!$C$2:$C$1737, $C6, 'Full Player List'!U$2:U$1737),0) -> 0.6 | J6: =IFERROR(AVERAGEIF('Full Player List'!$C$2:$C$1737, $C6, 'Full Player List'!V$2:V$1737),0) -> 8.4 | K6: =IFERROR(AVERAGEIF('Full Player List'!$C$2:$C$1737, $C6, 'Full Player List'!W$2:W$1737),0) -> 18 | L6: =IFERROR(AVERAGEIF('Full Player List'!$C$2:$C$1737, $C6, 'Full Player List'!X$2:X$1737),0) -> 1.7 | M6: =IFERROR(AVERAGEIF('Full Player List'!$C$2:$C$1737, $C6, 'Full Player List'!Y$2:Y$1737),0) -> 1 | N6: =IFERROR(AVERAGEIF('Full Player List'!$C$2:$C$1737, $C6, 'Full Player List'!Z$2:Z$1737),0) -> 0
A7: 351300 | B7: DT | C7: CJ West | D7: 2024 | G7: =IFERROR(AVERAGEIF('Full Player List'!$C$2:$C$1737, $C7, 'Full Player List'!S$2:S$1737),0) -> 0.4 | H7: =IFERROR(AVERAGEIF('Full Player List'!$C$2:$C$1737, $C7, 'Full Player List'!T$2:T$1737),0) -> 1 | I7: =IFERROR(AVERAGEIF('Full Player List'!$C$2:$C$1737, $C7, 'Full Player List'!U$2:U$1737),0) -> 1.8 | J7: =IFERROR(AVERAGEIF('Full Player List'!$C$2:$C$1737, $C7, 'Full Player List'!V$2:V$1737),0) -> 13.6 | K7: =IFERROR(AVERAGEIF('Full Player List'!$C$2:$C$1737, $C7, 'Full Player List'!W$2:W$1737),0) -> 30 | L7: =IFERROR(AVERAGEIF('Full Player List'!$C$2:$C$1737, $C7, 'Full Player List'!X$2:X$1737),0) -> 5.4 | M7: =IFERROR(AVERAGEIF('Full Player List'!$C$2:$C$1737, $C7, 'Full Player List'!Y$2:Y$1737),0) -> 0 | N7: =IFERROR(AVERAGEIF('Full Player List'!$C$2:$C$1737, $C7, 'Full Player List'!Z$2:Z$1737),0) -> 0
A8: 352239 | B8: DT | C8: Nash Hutmacher | D8: 2023 | G8: =IFERROR(AVERAGEIF('Full Player List'!$C$2:$C$1737, $C8, 'Full Player List'!S$2:S$1737),0) -> 0.66666667 | H8: =IFERROR(AVERAGEIF('Full Player List'!$C$2:$C$1737, $C8, 'Full Player List'!T$2:T$1737),0) -> 1.6666667 | I8: =IFERROR(AVERAGEIF('Full Player List'!$C$2:$C$1737, $C8, 'Full Player List'!U$2:U$1737),0) -> 2.1666667 | J8: =IFERROR(AVERAGEIF('Full Player List'!$C$2:$C$1737, $C8, 'Full Player List'!V$2:V$1737),0) -> 11.333333 | K8: =IFERROR(AVERAGEIF('Full Player List'!$C$2:$C$1737, $C8, 'Full Player List'!W$2:W$1737),0) -> 26.333333 | L8: =IFERROR(AVERAGEIF('Full Player List'!$C$2:$C$1737, $C8, 'Full Player List'!X$2:X$1737),0) -> 4.1666667 | M8: =IFERROR(AVERAGEIF('Full Player List'!$C$2:$C$1737, $C8, 'Full Player List'!Y$2:Y$1737),0) -> 0 | N8: =IFERROR(AVERAGEIF('Full Player List'!$C$2:$C$1737, $C8, 'Full Player List'!Z$2:Z$1737),0) -> 0
A9: 361567 | B9: DT | C9: Payton Page | D9: 2023 | G9: =IFERROR(AVERAGEIF('Full Player List'!$C$2:$C$1737, $C9, 'Full Player List'!S$2:S$1737),0) -> 0.5 | H9: =IFERROR(AVERAGEIF('Full Player List'!$C$2:$C$1737, $C9, 'Full Player List'!T$2:T$1737),0) -> 0.75 | I9: =IFERROR(AVERAGEIF('Full Player List'!$C$2:$C$1737, $C9, 'Full Player List'!U$2:U$1737),0) -> 0.125 | J9: =IFERROR(AVERAGEIF('Full Player List'!$C$2:$C$1737, $C9, 'Full Player List'!V$2:V$1737),0) -> 6.75 | K9: =IFERROR(AVERAGEIF('Full Player List'!$C$2:$C$1737, $C9, 'Full Player List'!W$2:W$1737),0) -> 14 | L9: =IFERROR(AVERAGEIF('Full Player List'!$C$2:$C$1737, $C9, 'Full Player List'!X$2:X$1737),0) -> 1.625 | M9: =IFERROR(AVERAGEIF('Full Player List'!$C$2:$C$1737, $C9, 'Full Player List'!Y$2:Y$1737),0) -> 1 | N9: =IFERROR(AVERAGEIF('Full Player List'!$C$2:$C$1737, $C9, 'Full Player List'!Z$2:Z$1737),0) -> 0.25
A10: 369216 | B10: DT | C10: Tommy Akingbesote | D10: 2023 | G10: =IFERROR(AVERAGEIF('Full Player List'!$C$2:$C$1737, $C10, 'Full Player List'!S$2:S$1737),0) -> 0.5 | H10: =IFERROR(AVERAGEIF('Full Player List'!$C$2:$C$1737, $C10, 'Full Player List'!T$2:T$1737),0) -> 0.25 | I10: =IFERROR(AVERAGEIF('Full Player List'!$C$2:$C$1737, $C10, 'Full Player List'!U$2:U$1737),0) -> 1 | J10: =IFERROR(AVERAGEIF('Full Player List'!$C$2:$C$1737, $C10, 'Full Player List'!V$2:V$1737),0) -> 11 | K10: =IFERROR(AVERAGEIF('Full Player List'!$C$2:$C$1737, $C10, 'Full Player List'!W$2:W$1737),0) -> 19.25 | L10: =IFERROR(AVERAGEIF('Full Player List'!$C$2:$C$1737, $C10, 'Full Player List'!X$2:X$1737),0) -> 1.875 | M10: =IFERROR(AVERAGEIF('Full Player List'!$C$2:$C$1737, $C10, 'Full Player List'!Y$2:Y$1737),0) -> 0 | N10: =IFERROR(AVERAGEIF('Full Player List'!$C$2:$C$1737, $C10, 'Full Player List'!Z$2:Z$1737),0) -> 0
A11: 386094 | B11: DT | C11: Jordan Phillips | D11: 2024 | G11: =IFERROR(AVERAGEIF('Full Player List'!$C$2:$C$1737, $C11, 'Full Player List'!S$2:S$1737),0) -> 0 | H11: =IFERROR(AVERAGEIF('Full Player List'!$C$2:$C$1737, $C11, 'Full Player List'!T$2:T$1737),0) -> 1.3333333 | I11: =IFERROR(AVERAGEIF('Full Player List'!$C$2:$C$1737, $C11, 'Full Player List'!U$2:U$1737),0) -> 0 | J11: =IFERROR(AVERAGEIF('Full Player List'!$C$2:$C$1737, $C11, 'Full Player List'!V$2:V$1737),0) -> 10.333333 | K11: =IFERROR(AVERAGEIF('Full Player List'!$C$2:$C$1737, $C11, 'Full Player List'!W$2:W$1737),0) -> 19.333333 | L11: =IFERROR(AVERAGEIF('Full Player List'!$C$2:$C$1737, $C11, 'Full Player List'!X$2:X$1737),0) -> 0.83333333 | M11: =IFERROR(AVERAGEIF('Full Player List'!$C$2:$C$1737, $C11, 'Full Player List'!Y$2:Y$1737),0) -> 0 | N11: =IFERROR(AVERAGEIF('Full Player List'!$C$2:$C$1737, $C11, 'Full Player List'!Z$2:Z$1737),0) -> 0
A12: 305093 | B12: DT | C12: Fabien Lovett | D12: 2023 | G12: =IFERROR(AVERAGEIF('Full Player List'!$C$2:$C$1737, $C12, 'Full Player List'!S$2:S$1737),0) -> 0.8 | H12: =IFERROR(AVERAGEIF('Full Player List'!$C$2:$C$1737, $C12, 'Full Player List'!T$2:T$1737),0) -> 0.4 | I12: =IFERROR(AVERAGEIF('Full Player List'!$C$2:$C$1737, $C12, 'Full Player List'!U$2:U$1737),0) -> 1.2 | J12: =IFERROR(AVERAGEIF('Full Player List'!$C$2:$C$1737, $C12, 'Full Player List'!V$2:V$1737),0) -> 7.4 | K12: =IFERROR(AVERAGEIF('Full Player List'!$C$2:$C$1737, $C12, 'Full Player List'!W$2:W$1737),0) -> 18.4 | L12: =IFERROR(AVERAGEIF('Full Player List'!$C$2:$C$1737, $C12, 'Full Player List'!X$2:X$1737),0) -> 2.9 | M12: =IFERROR(AVERAGEIF('Full Player List'!$C$2:$C$1737, $C12, 'Full Player List'!Y$2:Y$1737),0) -> 0 | N12: =IFERROR(AVERAGEIF('Full Player List'!$C$2:$C$1737, $C12, 'Full Player List'!Z$2:Z$1737),0) -> 0
A13: 306113 | B13: DT | C13: Tuli Letuligasenoa | D13: 2024 | G13: =IFERROR(AVERAGEIF('Full Player List'!$C$2:$C$1737, $C13, 'Full Player List'!S$2:S$1737),0) -> 1.4 | H13: =IFERROR(AVERAGEIF('Full Player List'!$C$2:$C$1737, $C13, 'Full Player List'!T$2:T$1737),0) -> 0.4 | I13: =IFERROR(AVERAGEIF('Full Player List'!$C$2:$C$1737, $C13, 'Full Player List'!U$2:U$1737),0) -> 0.4 | J13: =IFERROR(AVERAGEIF('Full Player List'!$C$2:$C$1737, $C13, 'Full Player List'!V$2:V$1737),0) -> 12.2 | K13: =IFERROR(AVERAGEIF('Full Player List'!$C$2:$C$1737, $C13, 'Full Player List'!W$2:W$1737),0) -> 22.2 | L13: =IFERROR(AVERAGEIF('Full Player List'!$C$2:$C$1737, $C13, 'Full Player List'!X$2:X$1737),0) -> 3.5 | M13: =IFERROR(AVERAGEIF('Full Player List'!$C$2:$C$1737, $C13, 'Full Player List'!Y$2:Y$1737),0) -> 1 | N13: =IFERROR(AVERAGEIF('Full Player List'!$C$2:$C$1737, $C13, 'Full Player List'!Z$2:Z$1737),0) -> 0
... A22: 351069 | B22: DT | C22: Logan Lee | D22: 2024 | G22: =IFERROR(AVERAGEIF('Full Player List'!$C$2:$C$1737, $C22, 'Full Player List'!S$2:S$1737),0) -> 1.75 | H22: =IFERROR(AVERAGEIF('Full Player List'!$C$2:$C$1737, $C22, 'Full Player List'!T$2:T$1737),0) -> 0.75 | I22: =IFERROR(AVERAGEIF('Full Player List'!$C$2:$C$1737, $C22, 'Full Player List'!U$2:U$1737),0) -> 2.25 | J22: =IFERROR(AVERAGEIF('Full Player List'!$C$2:$C$1737, $C22, 'Full Player List'!V$2:V$1737),0) -> 13.5 | K22: =IFERROR(AVERAGEIF('Full Player List'!$C$2:$C$1737, $C22, 'Full Player List'!W$2:W$1737),0) -> 37.75 | L22: =IFERROR(AVERAGEIF('Full Player List'!$C$2:$C$1737, $C22, 'Full Player List'!X$2:X$1737),0) -> 4.5 | M22: =IFERROR(AVERAGEIF('Full Player List'!$C$2:$C$1737, $C22, 'Full Player List'!Y$2:Y$1737),0) -> 0 | N22: =IFERROR(AVERAGEIF('Full Player List'!$C$2:$C$1737, $C22, 'Full Player List'!Z$2:Z$1737),0) -> 0

Sheet DE
A1: college_gsis_id | B1: position | C1: player_name | D1: season | E1: team | F1: school_code | G1: defense_pass_breakups | H1: defense_qb_hurries | I1: defense_sacks | J1: defense_solo_tackles | K1: defense_total_tackles | L1: defense_tackles_for_loss | M1: defense_interceptions | N1: defense_touchdowns
A2: 349029 | B2: DE | C2: Tyler Baron | G2: =IFERROR(AVERAGEIF('Full Player List'!$C$2:$C$1737, $C2, 'Full Player List'!S$2:S$1737),0) -> 0.8 | H2: =IFERROR(AVERAGEIF('Full Player List'!$C$2:$C$1737, $C2, 'Full Player List'!T$2:T$1737),0) -> 3.6 | I2: =IFERROR(AVERAGEIF('Full Player List'!$C$2:$C$1737, $C2, 'Full Player List'!U$2:U$1737),0) -> 3.8 | J2: =IFERROR(AVERAGEIF('Full Player List'!$C$2:$C$1737, $C2, 'Full Player List'!V$2:V$1737),0) -> 13 | K2: =IFERROR(AVERAGEIF('Full Player List'!$C$2:$C$1737, $C2, 'Full Player List'!W$2:W$1737),0) -> 27.2 | L2: =IFERROR(AVERAGEIF('Full Player List'!$C$2:$C$1737, $C2, 'Full Player List'!X$2:X$1737),0) -> 7.6 | M2: =IFERROR(AVERAGEIF('Full Player List'!$C$2:$C$1737, $C2, 'Full Player List'!Y$2:Y$1737),0) -> 0 | N2: =IFERROR(AVERAGEIF('Full Player List'!$C$2:$C$1737, $C2, 'Full Player List'!Z$2:Z$1737),0) -> 0
A3: 349308 | B3: DE | C3: Tyler Batty | G3: =IFERROR(AVERAGEIF('Full Player List'!$C$2:$C$1737, $C3, 'Full Player List'!S$2:S$1737),0) -> 0.4 | H3: =IFERROR(AVERAGEIF('Full Player List'!$C$2:$C$1737, $C3, 'Full Player List'!T$2:T$1737),0) -> 4.6 | I3: =IFERROR(AVERAGEIF('Full Player List'!$C$2:$C$1737, $C3, 'Full Player List'!U$2:U$1737),0) -> 3.3 | J3: =IFERROR(AVERAGEIF('Full Player List'!$C$2:$C$1737, $C3, 'Full Player List'!V$2:V$1737),0) -> 23.6 | K3: =IFERROR(AVERAGEIF('Full Player List'!$C$2:$C$1737, $C3, 'Full Player List'!W$2:W$1737),0) -> 42.6 | L3: =IFERROR(AVERAGEIF('Full Player List'!$C$2:$C$1737, $C3, 'Full Player List'!X$2:X$1737),0) -> 6.6 | M3: =IFERROR(AVERAGEIF('Full Player List'!$C$2:$C$1737, $C3, 'Full Player List'!Y$2:Y$1737),0) -> 2 | N3: =IFERROR(AVERAGEIF('Full Player List'!$C$2:$C$1737, $C3, 'Full Player List'!Z$2:Z$1737),0) -> 0
A4: 349348 | B4: DE | C4: Sean Martin | G4: =IFERROR(AVERAGEIF('Full Player List'!$C$2:$C$1737, $C4, 'Full Player List'!S$2:S$1737),0) -> 0.25 | H4: =IFERROR(AVERAGEIF('Full Player List'!$C$2:$C$1737, $C4, 'Full Player List'!T$2:T$1737),0) -> 3 | I4: =IFERROR(AVERAGEIF('Full Player List'!$C$2:$C$1737, $C4, 'Full Player List'!U$2:U$1737),0) -> 2.125 | J4: =IFERROR(AVERAGEIF('Full Player List'!$C$2:$C$1737, $C4, 'Full Player List'!V$2:V$1737),0) -> 11.25 | K4: =IFERROR(AVERAGEIF('Full Player List'!$C$2:$C$1737, $C4, 'Full Player List'!W$2:W$1737),0) -> 24.75 | L4: =IFERROR(AVERAGEIF('Full Player List'!$C$2:$C$1737, $C4, 'Full Player List'!X$2:X$1737),0) -> 4.75 | M4: =IFERROR(AVERAGEIF('Full Player List'!$C$2:$C$1737, $C4, 'Full Player List'!Y$2:Y$1737),0) -> 0 | N4: =IFERROR(AVERAGEIF('Full Player List'!$C$2:$C$1737, $C4, 'Full Player List'!Z$2:Z$1737),0) -> 0
A5: 350674 | B5: DE | C5: Antwuan Powell | G5: =IFERROR(AVERAGEIF('Full Player List'!$C$2:$C$1737, $C5, 'Full Player List'!S$2:S$1737),0) -> 0.25 | H5: =IFERROR(AVERAGEIF('Full Player List'!$C$2:$C$1737, $C5, 'Full Player List'!T$2:T$1737),0) -> 4.25 | I5: =IFERROR(AVERAGEIF('Full Player List'!$C$2:$C$1737, $C5, 'Full Player List'!U$2:U$1737),0) -> 7.375 | J5: =IFERROR(AVERAGEIF('Full Player List'!$C$2:$C$1737, $C5, 'Full Player List'!V$2:V$1737),0) -> 16.25 | K5: =IFERROR(AVERAGEIF('Full Player List'!$C$2:$C$1737, $C5, 'Full Player List'!W$2:W$1737),0) -> 28 | L5: =IFERROR(AVERAGEIF('Full Player List'!$C$2:$C$1737, $C5, 'Full Player List'!X$2:X$1737),0) -> 9.875 | M5: =IFERROR(AVERAGEIF('Full Player List'!$C$2:$C$1737, $C5, 'Full Player List'!Y$2:Y$1737),0) -> 0 | N5: =IFERROR(AVERAGEIF('Full Player List'!$C$2:$C$1737, $C5, 'Full Player List'!Z$2:Z$1737),0) -> 0
A6: 355296 | B6: DE | C6: Elijah Ponder | G6: =IFERROR(AVERAGEIF('Full Player List'!$C$2:$C$1737, $C6, 'Full Player List'!S$2:S$1737),0) -> 0.5 | H6: =IFERROR(AVERAGEIF('Full Player List'!$C$2:$C$1737, $C6, 'Full Player List'!T$2:T$1737),0) -> 0.25 | I6: =IFERROR(AVERAGEIF('Full Player List'!$C$2:$C$1737, $C6, 'Full Player List'!U$2:U$1737),0) -> 0.25 | J6: =IFERROR(AVERAGEIF('Full Player List'!$C$2:$C$1737, $C6, 'Full Player List'!V$2:V$1737),0) -> 2 | K6: =IFERROR(AVERAGEIF('Full Player List'!$C$2:$C$1737, $C6, 'Full Player List'!W$2:W$1737),0) -> 2.75 | L6: =IFERROR(AVERAGEIF('Full Player List'!$C$2:$C$1737, $C6, 'Full Player List'!X$2:X$1737),0) -> 0.875 | M6: =IFERROR(AVERAGEIF('Full Player List'!$C$2:$C$1737, $C6, 'Full Player List'!Y$2:Y$1737),0) -> 0 | N6: =IFERROR(AVERAGEIF('Full Player List'!$C$2:$C$1737, $C6, 'Full Player List'!Z$2:Z$1737),0) -> 0
A7: 368430 | B7: DE | C7: Johnny Walker | G7: =IFERROR(AVERAGEIF('Full Player List'!$C$2:$C$1737, $C7, 'Full Player List'!S$2:S$1737),0) -> 0.2 | H7: =IFERROR(AVERAGEIF('Full Player List'!$C$2:$C$1737, $C7, 'Full Player List'!T$2:T$1737),0) -> 3 | I7: =IFERROR(AVERAGEIF('Full Player List'!$C$2:$C$1737, $C7, 'Full Player List'!U$2:U$1737),0) -> 3.8 | J7: =IFERROR(AVERAGEIF('Full Player List'!$C$2:$C$1737, $C7, 'Full Player List'!V$2:V$1737),0) -> 10.4 | K7: =IFERROR(AVERAGEIF('Full Player List'!$C$2:$C$1737, $C7, 'Full Player List'!W$2:W$1737),0) -> 20 | L7: =IFERROR(AVERAGEIF('Full Player List'!$C$2:$C$1737, $C7, 'Full Player List'!X$2:X$1737),0) -> 5.3 | M7: =IFERROR(AVERAGEIF('Full Player List'!$C$2:$C$1737, $C7, 'Full Player List'!Y$2:Y$1737),0) -> 0 | N7: =IFERROR(AVERAGEIF('Full Player List'!$C$2:$C$1737, $C7, 'Full Player List'!Z$2:Z$1737),0) -> 0
A8: 305227 | B8: DE | C8: Eyabi Anoma | G8: =IFERROR(AVERAGEIF('Full Player List'!$C$2:$C$1737, $C8, 'Full Player List'!S$2:S$1737),0) -> 0.33333333 | H8: =IFERROR(AVERAGEIF('Full Player List'!$C$2:$C$1737, $C8, 'Full Player List'!T$2:T$1737),0) -> 3.6666667 | I8: =IFERROR(AVERAGEIF('Full Player List'!$C$2:$C$1737, $C8, 'Full Player List'!U$2:U$1737),0) -> 2.8333333 | J8: =IFERROR(AVERAGEIF('Full Player List'!$C$2:$C$1737, $C8, 'Full Player List'!V$2:V$1737),0) -> 10.333333 | K8: =IFERROR(AVERAGEIF('Full Player List'!$C$2:$C$1737, $C8, 'Full Player List'!W$2:W$1737),0) -> 24 | L8: =IFERROR(AVERAGEIF('Full Player List'!$C$2:$C$1737, $C8, 'Full Player List'!X$2:X$1737),0) -> 5.3333333 | M8: =IFERROR(AVERAGEIF('Full Player List'!$C$2:$C$1737, $C8, 'Full Player List'!Y$2:Y$1737),0) -> 0 | N8: =IFERROR(AVERAGEIF('Full Player List'!$C$2:$C$1737, $C8, 'Full Player List'!Z$2:Z$1737),0) -> 0
A9: 305905 | B9: DE | C9: Sundiata Anderson | G9: =IFERROR(AVERAGEIF('Full Player List'!$C$2:$C$1737, $C9, 'Full Player List'!S$2:S$1737),0) -> 0 | H9: =IFERROR(AVERAGEIF('Full Player List'!$C$2:$C$1737, $C9, 'Full Player List'!T$2:T$1737),0) -> 0 | I9: =IFERROR(AVERAGEIF('Full Player List'!$C$2:$C$1737, $C9, 'Full Player List'!U$2:U$1737),0) -> 0.125 | J9: =IFERROR(AVERAGEIF('Full Player List'!$C$2:$C$1737, $C9, 'Full Player List'!V$2:V$1737),0) -> 1.75 | K9: =IFERROR(AVERAGEIF('Full Player List'!$C$2:$C$1737, $C9, 'Full Player List'!W$2:W$1737),0) -> 2.25 | L9: =IFERROR(AVERAGEIF('Full Player List'!$C$2:$C$1737, $C9, 'Full Player List'!X$2:X$1737),0) -> 0.625 | M9: =IFERROR(AVERAGEIF('Full Player List'!$C$2:$C$1737, $C9, 'Full Player List'!Y$2:Y$1737),0) -> 0 | N9: =IFERROR(AVERAGEIF('Full Player List'!$C$2:$C$1737, $C9, 'Full Player List'!Z$2:Z$1737),0) -> 0
A10: 306298 | B10: DE | C10: Solomon Byrd | G10: =IFERROR(AVERAGEIF('Full Player List'!$C$2:$C$1737, $C10, 'Full Player List'!S$2:S$1737),0) -> 0.6 | H10: =IFERROR(AVERAGEIF('Full Player List'!$C$2:$C$1737, $C10, 'Full Player List'!T$2:T$1737),0) -> 1.6 | I10: =IFERROR(AVERAGEIF('Full Player List'!$C$2:$C$1737, $C10, 'Full Player List'!U$2:U$1737),0) -> 3.7 | J10: =IFERROR(AVERAGEIF('Full Player List'!$C$2:$C$1737, $C10, 'Full Player List'!V$2:V$1737),0) -> 17.8 | K10: =IFERROR(AVERAGEIF('Full Player List'!$C$2:$C$1737, $C10, 'Full Player List'!W$2:W$1737),0) -> 31.6 | L10: =IFERROR(AVERAGEIF('Full Player List'!$C$2:$C$1737, $C10, 'Full Player List'!X$2:X$1737),0) -> 5.6 | M10: =IFERROR(AVERAGEIF('Full Player List'!$C$2:$C$1737, $C10, 'Full Player List'!Y$2:Y$1737),0) -> 0 | N10: =IFERROR(AVERAGEIF('Full Player List'!$C$2:$C$1737, $C10, 'Full Player List'!Z$2:Z$1737),0) -> 0
A11: 324852 | B11: DE | C11: David Ugwoegbu | G11: =IFERROR(AVERAGEIF('Full Player List'!$C$2:$C$1737, $C11, 'Full Player List'!S$2:S$1737),0) -> 1 | H11: =IFERROR(AVERAGEIF('Full Player List'!$C$2:$C$1737, $C11, 'Full Player List'!T$2:T$1737),0) -> 2.2 | I11: =IFERROR(AVERAGEIF('Full Player List'!$C$2:$C$1737, $C11, 'Full Player List'!U$2:U$1737),0) -> 1.3 | J11: =IFERROR(AVERAGEIF('Full Player List'!$C$2:$C$1737, $C11, 'Full Player List'!V$2:V$1737),0) -> 26.4 | K11: =IFERROR(AVERAGEIF('Full Player List'!$C$2:$C$1737, $C11, 'Full Player List'!W$2:W$1737),0) -> 48.4 | L11: =IFERROR(AVERAGEIF('Full Player List'!$C$2:$C$1737, $C11, 'Full Player List'!X$2:X$1737),0) -> 4.4 | M11: =IFERROR(AVERAGEIF('Full Player List'!$C$2:$C$1737, $C11, 'Full Player List'!Y$2:Y$1737),0) -> 1 | N11: =IFERROR(AVERAGEIF('Full Player List'!$C$2:$C$1737, $C11, 'Full Player List'!Z$2:Z$1737),0) -> 0
A12: 325899 | B12: DE | C12: Gabriel Murphy | G12: =IFERROR(AVERAGEIF('Full Player List'!$C$2:$C$1737, $C12, 'Full Player List'!S$2:S$1737),0) -> 1.2 | H12: =IFERROR(AVERAGEIF('Full Player List'!$C$2:$C$1737, $C12, 'Full Player List'!T$2:T$1737),0) -> 3.8 | I12: =IFERROR(AVERAGEIF('Full Player List'!$C$2:$C$1737, $C12, 'Full Player List'!U$2:U$1737),0) -> 4.5 | J12: =IFERROR(AVERAGEIF('Full Player List'!$C$2:$C$1737, $C12, 'Full Player List'!V$2:V$1737),0) -> 14.4 | K12: =IFERROR(AVERAGEIF('Full Player List'!$C$2:$C$1737, $C12, 'Full Player List'!W$2:W$1737),0) -> 29.2 | L12: =IFERROR(AVERAGEIF('Full Player List'!$C$2:$C$1737, $C12, 'Full Player List'!X$2:X$1737),0) -> 7.6 | M12: =IFERROR(AVERAGEIF('Full Player List'!$C$2:$C$1737, $C12, 'Full Player List'!Y$2:Y$1737),0) -> 0 | N12: =IFERROR(AVERAGEIF('Full Player List'!$C$2:$C$1737, $C12, 'Full Player List'!Z$2:Z$1737),0) -> 0
A13: 327944 | B13: DE | C13: Mohamed Kamara | G13: =IFERROR(AVERAGEIF('Full Player List'!$C$2:$C$1737, $C13, 'Full Player List'!S$2:S$1737),0) -> 0.4 | H13: =IFERROR(AVERAGEIF('Full Player List'!$C$2:$C$1737, $C13, 'Full Player List'!T$2:T$1737),0) -> 5 | I13: =IFERROR(AVERAGEIF('Full Player List'!$C$2:$C$1737, $C13, 'Full Player List'!U$2:U$1737),0) -> 5.8 | J13: =IFERROR(AVERAGEIF('Full Player List'!$C$2:$C$1737, $C13, 'Full Player List'!V$2:V$1737),0) -> 18.4 | K13: =IFERROR(AVERAGEIF('Full Player List'!$C$2:$C$1737, $C13, 'Full Player List'!W$2:W$1737),0) -> 35.4 | L13: =IFERROR(AVERAGEIF('Full Player List'!$C$2:$C$1737, $C13, 'Full Player List'!X$2:X$1737),0) -> 8.8 | M13: =IFERROR(AVERAGEIF('Full Player List'!$C$2:$C$1737, $C13, 'Full Player List'!Y$2:Y$1737),0) -> 0 | N13: =IFERROR(AVERAGEIF('Full Player List'!$C$2:$C$1737, $C13, 'Full Player List'!Z$2:Z$1737),0) -> 0.2
A14: 328197 | B14: DE | C14: Khalid Duke | G14: =IFERROR(AVERAGEIF('Full Player List'!$C$2:$C$1737, $C14, 'Full Player List'!S$2:S$1737),0) -> 0.4 | H14: =IFERROR(AVERAGEIF('Full Player List'!$C$2:$C$1737, $C14, 'Full Player List'!T$2:T$1737),0) -> 2 | I14: =IFERROR(AVERAGEIF('Full Player List'!$C$2:$C$1737, $C14, 'Full Player List'!U$2:U$1737),0) -> 2.8 | J14: =IFERROR(AVERAGEIF('Full Player List'!$C$2:$C$1737, $C14, 'Full Player List'!V$2:V$1737),0) -> 13.6 | K14: =IFERROR(AVERAGEIF('Full Player List'!$C$2:$C$1737, $C14, 'Full Player List'!W$2:W$1737),0) -> 19.4 | L14: =IFERROR(AVERAGEIF('Full Player List'!$C$2:$C$1737, $C14, 'Full Player List'!X$2:X$1737),0) -> 4.2 | M14: =IFERROR(AVERAGEIF('Full Player List'!$C$2:$C$1737, $C14, 'Full Player List'!Y$2:Y$1737),0) -> 0 | N14: =IFERROR(AVERAGEIF('Full Player List'!$C$2:$C$1737, $C14, 'Full Player List'!Z$2:Z$1737),0) -> 0

Sheet IB
A1: college_gsis_id | B1: position | C1: player_name | D1: season | E1: team | F1: school_code | G1: defense_pass_breakups | H1: defense_qb_hurries | I1: defense_sacks | J1: defense_solo_tackles | K1: defense_total_tackles | L1: defense_tackles_for_loss | M1: defense_interceptions
A2: 325312 | B2: IB | C2: Matt Jones | G2: =AVERAGEIF('Full Player List'!$C$1:$C$1738, $C2, 'Full Player List'!S$1:S$1738) -> 2.8333333 | H2: =AVERAGEIF('Full Player List'!$C$1:$C$1738, $C2, 'Full Player List'!T$1:T$1738) -> 2.1666667 | I2: =AVERAGEIF('Full Player List'!$C$1:$C$1738, $C2, 'Full Player List'!U$1:U$1738) -> 2.1666667 | J2: =AVERAGEIF('Full Player List'!$C$1:$C$1738, $C2, 'Full Player List'!V$1:V$1738) -> 32.666667 | K2: =AVERAGEIF('Full Player List'!$C$1:$C$1738, $C2, 'Full Player List'!W$1:W$1738) -> 51 | L2: =AVERAGEIF('Full Player List'!$C$1:$C$1738, $C2, 'Full Player List'!X$1:X$1738) -> 5.9166667 | M2: =IFERROR(AVERAGEIF('Full Player List'!$C$1:$C$1738, $C2, 'Full Player List'!Y$1:Y$1738),0) -> 1
